<sdf version='1.7'>
  <world name='default'>
    <plugin name='ros_link_attacher_plugin' filename='libtm5700_gazebo.so'/>
    <gui fullscreen='0'>
      <camera name='user_camera'>
        <pose>1.08469 -1.14348 0.971507 -0 0.292 2.378</pose>
        <view_controller>orbit</view_controller>
        <projection_type>perspective</projection_type>
      </camera>
    </gui>
    <light name='sun' type='directional'>
      <cast_shadows>1</cast_shadows>
      <pose>0 0 10 0 -0 0</pose>
      <diffuse>0.8 0.8 0.8 1</diffuse>
      <specular>0.2 0.2 0.2 1</specular>
      <attenuation>
        <range>1000</range>
        <constant>0.9</constant>
        <linear>0.01</linear>
        <quadratic>0.001</quadratic>
      </attenuation>
      <direction>-0.5 0.1 -0.9</direction>
      <spot>
        <inner_angle>0</inner_angle>
        <outer_angle>0</outer_angle>
        <falloff>0</falloff>
      </spot>
    </light>
    <light name='spotlight' type='point'>
      <pose>10 -10 7 0 -0 0</pose>
      <diffuse>0.5 0.5 0.5 1</diffuse>
      <specular>0.1 0.1 0.1 1</specular>
      <attenuation>
        <range>50</range>
        <constant>0.5</constant>
        <linear>0.01</linear>
        <quadratic>0.001</quadratic>
      </attenuation>
      <cast_shadows>1</cast_shadows>
      <direction>0 0 -1</direction>
      <spot>
        <inner_angle>0</inner_angle>
        <outer_angle>0</outer_angle>
        <falloff>0</falloff>
      </spot>
    </light>
    <scene>
      <ambient>0.392 0.392 0.392 1</ambient>
      <background>0.784 0.784 0.784 1</background>
      <shadows>1</shadows>
    </scene>
    <gravity>0 0 -9.8</gravity>
    <magnetic_field>6e-06 2.3e-05 -4.2e-05</magnetic_field>
    <atmosphere type='adiabatic'/>
    <physics type='ode'>
      <max_step_size>0.001</max_step_size>
      <real_time_factor>1</real_time_factor>
      <real_time_update_rate>1000</real_time_update_rate>
    </physics>
    <wind/>
    <spherical_coordinates>
      <surface_model>EARTH_WGS84</surface_model>
      <latitude_deg>0</latitude_deg>
      <longitude_deg>0</longitude_deg>
      <elevation>0</elevation>
      <heading_deg>0</heading_deg>
    </spherical_coordinates>
    <model name='techman_robot'>
      <joint name='world_joint' type='fixed'>
        <pose relative_to='__model__'>0 0 0 0 -0 0</pose>
        <parent>world</parent>
        <child>base</child>
      </joint>
      <link name='base'>
        <pose relative_to='world_joint'>0 0 0 0 -0 0</pose>
        <inertial>
          <pose>0 0 0 0 -0 0</pose>
          <mass>1</mass>
          <inertia>
            <ixx>0.00110833</ixx>
            <ixy>0</ixy>
            <ixz>0</ixz>
            <iyy>0.00110833</iyy>
            <iyz>1.95933e-19</iyz>
            <izz>0.0018</izz>
          </inertia>
        </inertial>
        <collision name='base_link_collision'>
          <pose>0 0 0 1.5708 -0 0</pose>
          <geometry>
            <mesh>
              <scale>1 1 1</scale>
              <uri>/home/jules/Code/Oxilia/oxilia-prima-clean/src/sensors/robotic_arm/tm5700_simulation/techman_model/meshes/collision/tm5_base_c.stl</uri>
            </mesh>
          </geometry>
          <surface>
            <contact>
              <ode/>
            </contact>
            <bounce/>
            <friction>
              <torsional>
                <ode/>
              </torsional>
              <ode/>
            </friction>
          </surface>
          <max_contacts>10</max_contacts>
        </collision>
        <visual name='base_link_visual'>
          <pose>0 0 0 1.5708 -0 0</pose>
          <geometry>
            <mesh>
              <scale>1 1 1</scale>
              <uri>/home/jules/Code/Oxilia/oxilia-prima-clean/src/sensors/robotic_arm/tm5700_simulation/techman_model/meshes/visual/tm5_base.obj</uri>
            </mesh>
          </geometry>
        </visual>
        <self_collide>0</self_collide>
        <enable_wind>0</enable_wind>
        <kinematic>0</kinematic>
      </link>
      <joint name='shoulder_1_joint' type='revolute'>
        <pose relative_to='base'>0 0 0.1452 1.5708 -0 0</pose>
        <parent>base</parent>
        <child>shoulder_1_link</child>
        <axis>
          <xyz>0 1 0</xyz>
          <limit>
            <lower>-4.71239</lower>
            <upper>4.71239</upper>
            <effort>150</effort>
            <velocity>3.15</velocity>
          </limit>
          <dynamics>
            <damping>0</damping>
            <friction>0</friction>
            <spring_reference>0</spring_reference>
            <spring_stiffness>0</spring_stiffness>
          </dynamics>
        </axis>
      </joint>
      <link name='shoulder_1_link'>
        <pose relative_to='shoulder_1_joint'>0 0 0 0 -0 0</pose>
        <inertial>
          <pose>0 0 0 0 -0 0</pose>
          <mass>4.5</mass>
          <inertia>
            <ixx>0.0124875</ixx>
            <ixy>0</ixy>
            <ixz>0</ixz>
            <iyy>0.0081</iyy>
            <iyz>0</iyz>
            <izz>0.0124875</izz>
          </inertia>
        </inertial>
        <collision name='shoulder_1_link_collision'>
          <pose>0 0 0 0 -0 0</pose>
          <geometry>
            <mesh>
              <scale>1 1 1</scale>
              <uri>/home/jules/Code/Oxilia/oxilia-prima-clean/src/sensors/robotic_arm/tm5700_simulation/techman_model/meshes/collision/tm_400w_01_c.stl</uri>
            </mesh>
          </geometry>
          <surface>
            <contact>
              <ode/>
            </contact>
            <bounce/>
            <friction>
              <torsional>
                <ode/>
              </torsional>
              <ode/>
            </friction>
          </surface>
          <max_contacts>10</max_contacts>
        </collision>
        <visual name='shoulder_1_link_visual'>
          <pose>0 0 0 0 -0 0</pose>
          <geometry>
            <mesh>
              <scale>1 1 1</scale>
              <uri>/home/jules/Code/Oxilia/oxilia-prima-clean/src/sensors/robotic_arm/tm5700_simulation/techman_model/meshes/visual/tm_400w_01.obj</uri>
            </mesh>
          </geometry>
        </visual>
        <self_collide>0</self_collide>
        <enable_wind>0</enable_wind>
        <kinematic>0</kinematic>
      </link>
      <joint name='shoulder_2_joint' type='revolute'>
        <pose relative_to='shoulder_1_link'>0 0 0.146 0 -0 0</pose>
        <parent>shoulder_1_link</parent>
        <child>arm_1_link</child>
        <axis>
          <xyz>0 0 -1</xyz>
          <limit>
            <lower>-3.14159</lower>
            <upper>3.14159</upper>
            <effort>150</effort>
            <velocity>3.15</velocity>
          </limit>
          <dynamics>
            <damping>0</damping>
            <friction>0</friction>
            <spring_reference>0</spring_reference>
            <spring_stiffness>0</spring_stiffness>
          </dynamics>
        </axis>
      </joint>
      <link name='arm_1_link'>
        <pose relative_to='shoulder_2_joint'>0 0 0 0 -0 0</pose>
        <inertial>
          <pose>0 0.1645 0 0 -0 0</pose>
          <mass>11</mass>
          <inertia>
            <ixx>0.109121</ixx>
            <ixy>0</ixy>
            <ixz>0</ixz>
            <iyy>0.0198</iyy>
            <iyz>0</iyz>
            <izz>0.109121</izz>
          </inertia>
        </inertial>
        <collision name='arm_1_link_collision'>
          <pose>0 0 0 0 -0 0</pose>
          <geometry>
            <mesh>
              <scale>1 1 1</scale>
              <uri>/home/jules/Code/Oxilia/oxilia-prima-clean/src/sensors/robotic_arm/tm5700_simulation/techman_model/meshes/collision/tm5_700_arm1_c.stl</uri>
            </mesh>
          </geometry>
          <surface>
            <contact>
              <ode/>
            </contact>
            <bounce/>
            <friction>
              <torsional>
                <ode/>
              </torsional>
              <ode/>
            </friction>
          </surface>
          <max_contacts>10</max_contacts>
        </collision>
        <visual name='arm_1_link_visual'>
          <pose>0 0 0 0 -0 0</pose>
          <geometry>
            <mesh>
              <scale>1 1 1</scale>
              <uri>/home/jules/Code/Oxilia/oxilia-prima-clean/src/sensors/robotic_arm/tm5700_simulation/techman_model/meshes/visual/tm5_700_arm1.obj</uri>
            </mesh>
          </geometry>
        </visual>
        <self_collide>0</self_collide>
        <enable_wind>0</enable_wind>
        <kinematic>0</kinematic>
      </link>
      <joint name='elbow_joint' type='revolute'>
        <pose relative_to='arm_1_link'>0 0.329 -0.1297 0 -0 0</pose>
        <parent>arm_1_link</parent>
        <child>arm_2_link</child>
        <axis>
          <xyz>0 0 -1</xyz>
          <limit>
            <lower>-3.14159</lower>
            <upper>3.14159</upper>
            <effort>150</effort>
            <velocity>3.15</velocity>
          </limit>
          <dynamics>
            <damping>0</damping>
            <friction>0</friction>
            <spring_reference>0</spring_reference>
            <spring_stiffness>0</spring_stiffness>
          </dynamics>
        </axis>
      </joint>
      <link name='arm_2_link'>
        <pose relative_to='elbow_joint'>0 0 0 0 -0 0</pose>
        <inertial>
          <pose>0 0.15575 0 0 -0 0</pose>
          <mass>2.5</mass>
          <inertia>
            <ixx>0.0214807</ixx>
            <ixy>0</ixy>
            <ixz>0</ixz>
            <iyy>0.00253125</iyy>
            <iyz>0</iyz>
            <izz>0.0214807</izz>
          </inertia>
        </inertial>
        <collision name='arm_2_link_collision'>
          <pose>0 0 0 0 -0 0</pose>
          <geometry>
            <mesh>
              <scale>1 1 1</scale>
              <uri>/home/jules/Code/Oxilia/oxilia-prima-clean/src/sensors/robotic_arm/tm5700_simulation/techman_model/meshes/collision/tm5_700_arm2_c.stl</uri>
            </mesh>
          </geometry>
          <surface>
            <contact>
              <ode/>
            </contact>
            <bounce/>
            <friction>
              <torsional>
                <ode/>
              </torsional>
              <ode/>
            </friction>
          </surface>
          <max_contacts>10</max_contacts>
        </collision>
        <visual name='arm_2_link_visual'>
          <pose>0 0 0 0 -0 0</pose>
          <geometry>
            <mesh>
              <scale>1 1 1</scale>
              <uri>/home/jules/Code/Oxilia/oxilia-prima-clean/src/sensors/robotic_arm/tm5700_simulation/techman_model/meshes/visual/tm5_700_arm2.obj</uri>
            </mesh>
          </geometry>
        </visual>
        <self_collide>0</self_collide>
        <enable_wind>0</enable_wind>
        <kinematic>0</kinematic>
      </link>
      <joint name='wrist_1_joint' type='revolute'>
        <pose relative_to='arm_2_link'>0 0.3115 0.106 0 -0 0</pose>
        <parent>arm_2_link</parent>
        <child>wrist_1_link</child>
        <axis>
          <xyz>0 0 -1</xyz>
          <limit>
            <lower>-3.14159</lower>
            <upper>3.14159</upper>
            <effort>150</effort>
            <velocity>3.15</velocity>
          </limit>
          <dynamics>
            <damping>0</damping>
            <friction>0</friction>
            <spring_reference>0</spring_reference>
            <spring_stiffness>0</spring_stiffness>
          </dynamics>
        </axis>
      </joint>
      <link name='wrist_1_link'>
        <pose relative_to='wrist_1_joint'>0 0 0 0 -0 0</pose>
        <inertial>
          <pose>0 0 0 0 -0 0</pose>
          <mass>1.45</mass>
          <inertia>
            <ixx>0.00116906</ixx>
            <ixy>0</ixy>
            <ixz>0</ixz>
            <iyy>0.00146813</iyy>
            <iyz>0</iyz>
            <izz>0.00116906</izz>
          </inertia>
        </inertial>
        <collision name='wrist_1_link_collision'>
          <pose>0 0 0 0 -0 0</pose>
          <geometry>
            <mesh>
              <scale>1 1 1</scale>
              <uri>/home/jules/Code/Oxilia/oxilia-prima-clean/src/sensors/robotic_arm/tm5700_simulation/techman_model/meshes/collision/tm_100w_01_c.stl</uri>
            </mesh>
          </geometry>
          <surface>
            <contact>
              <ode/>
            </contact>
            <bounce/>
            <friction>
              <torsional>
                <ode/>
              </torsional>
              <ode/>
            </friction>
          </surface>
          <max_contacts>10</max_contacts>
        </collision>
        <visual name='wrist_1_link_visual'>
          <pose>0 0 0 0 -0 0</pose>
          <geometry>
            <mesh>
              <scale>1 1 1</scale>
              <uri>/home/jules/Code/Oxilia/oxilia-prima-clean/src/sensors/robotic_arm/tm5700_simulation/techman_model/meshes/visual/tm_100w_01.obj</uri>
            </mesh>
          </geometry>
        </visual>
        <self_collide>0</self_collide>
        <enable_wind>0</enable_wind>
        <kinematic>0</kinematic>
      </link>
      <joint name='wrist_2_joint' type='revolute'>
        <pose relative_to='wrist_1_link'>0 0.106 0 0 -0 0</pose>
        <parent>wrist_1_link</parent>
        <child>wrist_2_link</child>
        <axis>
          <xyz>0 1 0</xyz>
          <limit>
            <lower>-3.14159</lower>
            <upper>3.14159</upper>
            <effort>150</effort>
            <velocity>3.15</velocity>
          </limit>
          <dynamics>
            <damping>0</damping>
            <friction>0</friction>
            <spring_reference>0</spring_reference>
            <spring_stiffness>0</spring_stiffness>
          </dynamics>
        </axis>
      </joint>
      <link name='wrist_2_link'>
        <pose relative_to='wrist_2_joint'>0 0 0 0 -0 0</pose>
        <inertial>
          <pose>0 0 0 0 -0 0</pose>
          <mass>1.45</mass>
          <inertia>
            <ixx>0.00247406</ixx>
            <ixy>0</ixy>
            <ixz>0</ixz>
            <iyy>0.00247406</iyy>
            <iyz>0</iyz>
            <izz>0.00146813</izz>
          </inertia>
        </inertial>
        <collision name='wrist_2_link_collision'>
          <pose>0 0 0 0 -0 0</pose>
          <geometry>
            <mesh>
              <scale>1 1 1</scale>
              <uri>/home/jules/Code/Oxilia/oxilia-prima-clean/src/sensors/robotic_arm/tm5700_simulation/techman_model/meshes/collision/tm_100w_02_c.stl</uri>
            </mesh>
          </geometry>
          <surface>
            <contact>
              <ode/>
            </contact>
            <bounce/>
            <friction>
              <torsional>
                <ode/>
              </torsional>
              <ode/>
            </friction>
          </surface>
          <max_contacts>10</max_contacts>
        </collision>
        <visual name='wrist_2_link_visual'>
          <pose>0 0 0 0 -0 0</pose>
          <geometry>
            <mesh>
              <scale>1 1 1</scale>
              <uri>/home/jules/Code/Oxilia/oxilia-prima-clean/src/sensors/robotic_arm/tm5700_simulation/techman_model/meshes/visual/tm_100w_02.obj</uri>
            </mesh>
          </geometry>
        </visual>
        <self_collide>0</self_collide>
        <enable_wind>0</enable_wind>
        <kinematic>0</kinematic>
      </link>
      <joint name='wrist_3_joint' type='revolute'>
        <pose relative_to='wrist_2_link'>0 0 0.11315 0 -0 0</pose>
        <parent>wrist_2_link</parent>
        <child>wrist_3_link</child>
        <axis>
          <xyz>0 0 1</xyz>
          <limit>
            <lower>-4.71239</lower>
            <upper>4.71239</upper>
            <effort>150</effort>
            <velocity>3.15</velocity>
          </limit>
          <dynamics>
            <damping>0</damping>
            <friction>0</friction>
            <spring_reference>0</spring_reference>
            <spring_stiffness>0</spring_stiffness>
          </dynamics>
        </axis>
      </joint>
      <link name='wrist_3_link'>
        <pose relative_to='wrist_3_joint'>0 0 0 0 -0 0</pose>
        <inertial>
          <pose>0 2e-06 1e-06 0 -0 0</pose>
          <mass>0.40001</mass>
          <inertia>
            <ixx>0.000683592</ixx>
            <ixy>0</ixy>
            <ixz>0</ixz>
            <iyy>0.000683528</iyy>
            <iyz>-4.24817e-08</iyz>
            <izz>0.000406064</izz>
          </inertia>
        </inertial>
        <collision name='wrist_3_link_collision'>
          <pose>0 0 0 0 -0 0</pose>
          <geometry>
            <mesh>
              <scale>1 1 1</scale>
              <uri>/home/jules/Code/Oxilia/oxilia-prima-clean/src/sensors/robotic_arm/tm5700_simulation/techman_model/meshes/collision/tm_ee_c.stl</uri>
            </mesh>
          </geometry>
          <surface>
            <contact>
              <ode/>
            </contact>
            <bounce/>
            <friction>
              <torsional>
                <ode/>
              </torsional>
              <ode/>
            </friction>
          </surface>
          <max_contacts>10</max_contacts>
        </collision>
        <visual name='wrist_3_link_visual'>
          <pose>0 0 0 0 -0 0</pose>
          <geometry>
            <mesh>
              <scale>1 1 1</scale>
              <uri>/home/jules/Code/Oxilia/oxilia-prima-clean/src/sensors/robotic_arm/tm5700_simulation/techman_model/meshes/visual/tm_ee.obj</uri>
            </mesh>
          </geometry>
        </visual>
        <gravity>1</gravity>
        <velocity_decay/>
        <sensor name='camera1' type='camera'>
          <update_rate>30</update_rate>
          <camera name='head'>
            <image>
              <width>2592</width>
              <height>1944</height>
              <format>R8G8B8</format>
            </image>
            <lens>
              <intrinsics>
                <fx>662.023</fx>
                <fy>2662.02</fy>
                <cx>1296</cx>
                <cy>972</cy>
                <s>0</s>
              </intrinsics>
              <type>stereographic</type>
              <scale_to_hfov>1</scale_to_hfov>
            </lens>
            <clip>
              <near>0.001</near>
              <far>300</far>
            </clip>
            <noise>
              <type>gaussian</type>
              <mean>0</mean>
              <stddev>0.007</stddev>
            </noise>
            <horizontal_fov>1.047</horizontal_fov>
          </camera>
          <plugin name='camera_controller' filename='libgazebo_ros_camera.so'>
            <alwaysOn>1</alwaysOn>
            <visualize>1</visualize>
            <cameraName>tmcamera_gazebo</cameraName>
            <imageTopicName>image</imageTopicName>
            <cameraInfoTopicName>camera_info</cameraInfoTopicName>
            <frameName>camera_link</frameName>
            <hackBaseline>0.07</hackBaseline>
            <distortionK1>0.0</distortionK1>
            <distortionK2>0.0</distortionK2>
            <distortionK3>0.0</distortionK3>
            <distortionT1>0.0</distortionT1>
            <distortionT2>0.0</distortionT2>
            <robotNamespace>/</robotNamespace>
          </plugin>
          <pose>0 0.07969 0.05331 0 -0 0</pose>
        </sensor>
        <self_collide>0</self_collide>
        <enable_wind>0</enable_wind>
        <kinematic>0</kinematic>
      </link>
      <static>0</static>
      <plugin name='gazebo_ros_control' filename='libgazebo_ros_control.so'>
        <legacyModeNS>1</legacyModeNS>
        <robotNamespace>/</robotNamespace>
      </plugin>
      <pose>0 0 0 0 -0 0</pose>
    </model>
    <state world_name='default'>
      <sim_time>121 594000000</sim_time>
      <real_time>124 340890310</real_time>
      <wall_time>1611088546 730652013</wall_time>
      <iterations>121594</iterations>
      <model name='techman_robot'>
        <pose>-0 0 1e-06 -0.000215 -0 0</pose>
        <scale>1 1 1</scale>
        <link name='arm_1_link'>
          <pose>5.9e-05 -0.14597 0.145121 1.57136 4e-05 0.000406</pose>
          <velocity>-0 -0 0 0 1e-06 -1e-06</velocity>
          <acceleration>-0 -0 0 0 -0 0</acceleration>
          <wrench>-0 -0 0 0 -0 0</wrench>
        </link>
        <link name='arm_2_link'>
          <pose>2e-05 -0.016457 0.474194 1.57136 4e-05 0.000406</pose>
          <velocity>0 0 -0 0 1e-06 -1e-06</velocity>
          <acceleration>0 0 0 0 -0 0</acceleration>
          <wrench>0 0 0 0 -0 0</wrench>
        </link>
        <link name='base'>
          <pose>-0 0 1e-06 -0.000215 -0 0</pose>
          <velocity>0 0 -0 0 -0 0</velocity>
          <acceleration>0 0 -0 0 -0 0</acceleration>
          <wrench>0 0 -0 0 -0 0</wrench>
        </link>
        <link name='shoulder_1_link'>
          <pose>-0 3e-05 0.145198 1.57128 -0 0.000406</pose>
          <velocity>-0 -0 0 0 0 -1e-06</velocity>
          <acceleration>-0 -0 0 0 -0 0</acceleration>
          <wrench>-0 -0 0 0 -0 0</wrench>
        </link>
        <link name='wrist_1_link'>
          <pose>7.5e-05 -0.122632 0.785633 1.57136 3.9e-05 0.000406</pose>
          <velocity>1e-06 0 -0 0 1e-06 -1e-06</velocity>
          <acceleration>0 0 0 0 -0 0</acceleration>
          <wrench>0 0 0 0 -0 0</wrench>
        </link>
        <link name='wrist_2_link'>
          <pose>8e-05 -0.122694 0.891633 1.57139 3.9e-05 0.000388</pose>
          <velocity>1e-06 0 -0 0 1e-06 -1e-06</velocity>
          <acceleration>0 0 0 0 -0 0</acceleration>
          <wrench>0 0 0 0 -0 0</wrench>
        </link>
        <link name='wrist_3_link'>
          <pose>0.000124 -0.235844 0.891565 1.57139 3.7e-05 0.000388</pose>
          <velocity>1e-06 0 -0 0 1e-06 -1e-06</velocity>
          <acceleration>0 -0 -0 0 -0 0</acceleration>
          <wrench>0 -0 -0 0 -0 0</wrench>
        </link>
      </model>
      <light name='spotlight'>
        <pose>10 -10 7 0 -0 0</pose>
      </light>
      <light name='sun'>
        <pose>0 0 10 0 -0 0</pose>
      </light>
    </state>
  </world>
</sdf>
